Workbook
Name FILTER: MONITORING!$E:$AG

Sheet Recipients REF
A1: =IFERROR(__xludf.DUMMYFUNCTION("IMPORTRANGE(""https://docs.google.com/spreadsheets/d/1SbJSGn0EFbAIXgek3pE0WQkKMu5cg3viyDcV21CNd-w/edit?gid=0#gid=0"",""Tractor!A:T"")"),"") | B1: =IFERROR(__xludf.DUMMYFUNCTION("""COMPUTED_VALUE"""),"FOUR WHEEL TRACTOR WITH IMPLEMENTS") -> FOUR WHEEL TRACTOR WITH IMPLEMENTS | E1: =IFERROR(__xludf.DUMMYFUNCTION("""COMPUTED_VALUE"""),4.0) -> 4
A2: =IFERROR(__xludf.DUMMYFUNCTION("""COMPUTED_VALUE"""),"NO") -> NO | C2: =IFERROR(__xludf.DUMMYFUNCTION("""COMPUTED_VALUE"""),"Address") -> Address | D2: =IFERROR(__xludf.DUMMYFUNCTION("""COMPUTED_VALUE"""),"CONTACT PERSON") -> CONTACT PERSON | E2: =IFERROR(__xludf.DUMMYFUNCTION("""COMPUTED_VALUE"""),"CONTACT NUMBER") -> CONTACT NUMBER | F2: =IFERROR(__xludf.DUMMYFUNCTION("""COMPUTED_VALUE"""),"Project REF") -> Project REF | H2: =IFERROR(__xludf.DUMMYFUNCTION("""COMPUTED_VALUE"""),"DR NO.") -> DR NO. | I2: =IFERROR(__xludf.DUMMYFUNCTION("""COMPUTED_VALUE"""),"Tractor SN") -> Tractor SN | J2: =IFERROR(__xludf.DUMMYFUNCTION("""COMPUTED_VALUE"""),"Tractor EN") -> Tractor EN | K2: =IFERROR(__xludf.DUMMYFUNCTION("""COMPUTED_VALUE"""),"Front Loader SN") -> Front Loader SN | L2: =IFERROR(__xludf.DUMMYFUNCTION("""COMPUTED_VALUE"""),"Rotavator SN") -> Rotavator SN | M2: =IFERROR(__xludf.DUMMYFUNCTION("""COMPUTED_VALUE"""),"Disc Plow SN") -> Disc Plow SN | O2: =IFERROR(__xludf.DUMMYFUNCTION("""COMPUTED_VALUE"""),"Barangay") -> Barangay | Q2: =IFERROR(__xludf.DUMMYFUNCTION("""COMPUTED_VALUE"""),"Province") -> Province | R2: =IFERROR(__xludf.DUMMYFUNCTION("""COMPUTED_VALUE"""),"REGION") -> REGION
A3: =IFERROR(__xludf.DUMMYFUNCTION("""COMPUTED_VALUE"""),1.0) -> 1 | B3: =IFERROR(__xludf.DUMMYFUNCTION("""COMPUTED_VALUE"""),"TUBUAN-TANZA IRRIGATORS ASSOCIATION, INC.") -> TUBUAN-TANZA IRRIGATORS ASSOCIATION, INC. | C3: =IFERROR(__xludf.DUMMYFUNCTION("""COMPUTED_VALUE"""),"TUBUAN, PILA, LAGUNA") -> TUBUAN, PILA, LAGUNA | D3: =IFERROR(__xludf.DUMMYFUNCTION("""COMPUTED_VALUE"""),"Virgilio Cortes") -> Virgilio Cortes | E3: =IFERROR(__xludf.DUMMYFUNCTION("""COMPUTED_VALUE"""),"0935 4386 214") -> 0935 4386 214 | F3: =IFERROR(__xludf.DUMMYFUNCTION("""COMPUTED_VALUE"""),"RCEF 23-08-20 Rebidding") -> RCEF 23-08-20 Rebidding | G3: =IFERROR(__xludf.DUMMYFUNCTION("""COMPUTED_VALUE"""),1.0) -> 1 | H3: =IFERROR(__xludf.DUMMYFUNCTION("""COMPUTED_VALUE"""),16765.0) -> 16765 | I3: =IFERROR(__xludf.DUMMYFUNCTION("""COMPUTED_VALUE"""),"KMC5825AAPFPV0036") -> KMC5825AAPFPV0036 | J3: =IFERROR(__xludf.DUMMYFUNCTION("""COMPUTED_VALUE"""),"PTS100033") -> PTS100033 | K3: =IFERROR(__xludf.DUMMYFUNCTION("""COMPUTED_VALUE"""),"R-SERIES 001 PH") -> R-SERIES 001 PH | L3: =IFERROR(__xludf.DUMMYFUNCTION("""COMPUTED_VALUE"""),"WR LSGW 0001") -> WR LSGW 0001 | M3: =IFERROR(__xludf.DUMMYFUNCTION("""COMPUTED_VALUE"""),"WR WDP 0001") -> WR WDP 0001 | O3: =IFERROR(__xludf.DUMMYFUNCTION("""COMPUTED_VALUE"""),"Tubuan") -> Tubuan | P3: =IFERROR(__xludf.DUMMYFUNCTION("""COMPUTED_VALUE"""),"Pila") -> Pila | Q3: =IFERROR(__xludf.DUMMYFUNCTION("""COMPUTED_VALUE"""),"Laguna") -> Laguna | R3: =IFERROR(__xludf.DUMMYFUNCTION("""COMPUTED_VALUE"""),"4A") -> 4A
A4: =IFERROR(__xludf.DUMMYFUNCTION("""COMPUTED_VALUE"""),2.0) -> 2 | B4: =IFERROR(__xludf.DUMMYFUNCTION("""COMPUTED_VALUE"""),"PILA LAGUNA AGRICULTURE COOPERATIVE (PILAC)") -> PILA LAGUNA AGRICULTURE COOPERATIVE (PILAC) | C4: =IFERROR(__xludf.DUMMYFUNCTION("""COMPUTED_VALUE"""),"PANSOL, PILA, LAGUNA") -> PANSOL, PILA, LAGUNA | D4: =IFERROR(__xludf.DUMMYFUNCTION("""COMPUTED_VALUE"""),"BENJAMIN MANUAL") -> BENJAMIN MANUAL | E4: =IFERROR(__xludf.DUMMYFUNCTION("""COMPUTED_VALUE"""),9.750884823E9) -> 9750884823 | F4: =IFERROR(__xludf.DUMMYFUNCTION("""COMPUTED_VALUE"""),"RCEF 23-08-20 Rebidding") -> RCEF 23-08-20 Rebidding | G4: =IFERROR(__xludf.DUMMYFUNCTION("""COMPUTED_VALUE"""),1.0) -> 1 | H4: =IFERROR(__xludf.DUMMYFUNCTION("""COMPUTED_VALUE"""),16767.0) -> 16767 | I4: =IFERROR(__xludf.DUMMYFUNCTION("""COMPUTED_VALUE"""),"KMC5825ALPFPV0037") -> KMC5825ALPFPV0037 | J4: =IFERROR(__xludf.DUMMYFUNCTION("""COMPUTED_VALUE"""),"PTS100030") -> PTS100030 | K4: =IFERROR(__xludf.DUMMYFUNCTION("""COMPUTED_VALUE"""),"R-SERIES 005 PH") -> R-SERIES 005 PH | L4: =IFERROR(__xludf.DUMMYFUNCTION("""COMPUTED_VALUE"""),"WR LSGW 0003") -> WR LSGW 0003 | M4: =IFERROR(__xludf.DUMMYFUNCTION("""COMPUTED_VALUE"""),"WR WDP 0003") -> WR WDP 0003 | O4: =IFERROR(__xludf.DUMMYFUNCTION("""COMPUTED_VALUE"""),"Pansol") -> Pansol | P4: =IFERROR(__xludf.DUMMYFUNCTION("""COMPUTED_VALUE"""),"Pila") -> Pila | Q4: =IFERROR(__xludf.DUMMYFUNCTION("""COMPUTED_VALUE"""),"Laguna") -> Laguna | R4: =IFERROR(__xludf.DUMMYFUNCTION("""COMPUTED_VALUE"""),"4A") -> 4A
A5: =IFERROR(__xludf.DUMMYFUNCTION("""COMPUTED_VALUE"""),3.0) -> 3 | B5: =IFERROR(__xludf.DUMMYFUNCTION("""COMPUTED_VALUE"""),"STO. DOMINGO-MAITIM IRRIGATORS ASSOCIATION, INC.") -> STO. DOMINGO-MAITIM IRRIGATORS ASSOCIATION, INC. | C5: =IFERROR(__xludf.DUMMYFUNCTION("""COMPUTED_VALUE"""),"MAITIM, BAY, LAGUNA") -> MAITIM, BAY, LAGUNA | D5: =IFERROR(__xludf.DUMMYFUNCTION("""COMPUTED_VALUE"""),"#N/A") -> #N/A | E5: =IFERROR(__xludf.DUMMYFUNCTION("""COMPUTED_VALUE"""),"#N/A") -> #N/A | F5: =IFERROR(__xludf.DUMMYFUNCTION("""COMPUTED_VALUE"""),"RCEF 23-08-20 Rebidding") -> RCEF 23-08-20 Rebidding | G5: =IFERROR(__xludf.DUMMYFUNCTION("""COMPUTED_VALUE"""),1.0) -> 1 | H5: =IFERROR(__xludf.DUMMYFUNCTION("""COMPUTED_VALUE"""),16768.0) -> 16768 | I5: =IFERROR(__xludf.DUMMYFUNCTION("""COMPUTED_VALUE"""),"KMC5825AEPFPV0039") -> KMC5825AEPFPV0039 | J5: =IFERROR(__xludf.DUMMYFUNCTION("""COMPUTED_VALUE"""),"PTS100001") -> PTS100001 | K5: =IFERROR(__xludf.DUMMYFUNCTION("""COMPUTED_VALUE"""),"R-SERIES 019 PH") -> R-SERIES 019 PH | L5: =IFERROR(__xludf.DUMMYFUNCTION("""COMPUTED_VALUE"""),"WR LSGW 0002") -> WR LSGW 0002 | M5: =IFERROR(__xludf.DUMMYFUNCTION("""COMPUTED_VALUE"""),"WR WDP 0002") -> WR WDP 0002 | O5: =IFERROR(__xludf.DUMMYFUNCTION("""COMPUTED_VALUE"""),"Maitim") -> Maitim | P5: =IFERROR(__xludf.DUMMYFUNCTION("""COMPUTED_VALUE"""),"Bay") -> Bay | Q5: =IFERROR(__xludf.DUMMYFUNCTION("""COMPUTED_VALUE"""),"Laguna") -> Laguna | R5: =IFERROR(__xludf.DUMMYFUNCTION("""COMPUTED_VALUE"""),"4A") -> 4A
A6: =IFERROR(__xludf.DUMMYFUNCTION("""COMPUTED_VALUE"""),4.0) -> 4 | B6: =IFERROR(__xludf.DUMMYFUNCTION("""COMPUTED_VALUE"""),"BAGONG SAMAHAN NG MAGSASAKA NG PILA, LAGUNA, INC.") -> BAGONG SAMAHAN NG MAGSASAKA NG PILA, LAGUNA, INC. | C6: =IFERROR(__xludf.DUMMYFUNCTION("""COMPUTED_VALUE"""),"STA CLARA SUR, PILA, LAGUNA") -> STA CLARA SUR, PILA, LAGUNA | D6: =IFERROR(__xludf.DUMMYFUNCTION("""COMPUTED_VALUE"""),"Ernesto S. Napao") -> Ernesto S. Napao | E6: =IFERROR(__xludf.DUMMYFUNCTION("""COMPUTED_VALUE"""),9.338124621E9) -> 9338124621 | F6: =IFERROR(__xludf.DUMMYFUNCTION("""COMPUTED_VALUE"""),"RCEF 23-08-20 Rebidding") -> RCEF 23-08-20 Rebidding | G6: =IFERROR(__xludf.DUMMYFUNCTION("""COMPUTED_VALUE"""),1.0) -> 1 | H6: =IFERROR(__xludf.DUMMYFUNCTION("""COMPUTED_VALUE"""),16769.0) -> 16769 | I6: =IFERROR(__xludf.DUMMYFUNCTION("""COMPUTED_VALUE"""),"KMC5825AJPFPV0016") -> KMC5825AJPFPV0016 | J6: =IFERROR(__xludf.DUMMYFUNCTION("""COMPUTED_VALUE"""),"PTS100028") -> PTS100028 | K6: =IFERROR(__xludf.DUMMYFUNCTION("""COMPUTED_VALUE"""),"R-SERIES 010 PH") -> R-SERIES 010 PH | L6: =IFERROR(__xludf.DUMMYFUNCTION("""COMPUTED_VALUE"""),"WR LSGW 0004") -> WR LSGW 0004 | M6: =IFERROR(__xludf.DUMMYFUNCTION("""COMPUTED_VALUE"""),"WR WDP 0004") -> WR WDP 0004 | O6: =IFERROR(__xludf.DUMMYFUNCTION("""COMPUTED_VALUE"""),"Sta Clara Sur") -> Sta Clara Sur | P6: =IFERROR(__xludf.DUMMYFUNCTION("""COMPUTED_VALUE"""),"Pila") -> Pila | Q6: =IFERROR(__xludf.DUMMYFUNCTION("""COMPUTED_VALUE"""),"Laguna") -> Laguna | R6: =IFERROR(__xludf.DUMMYFUNCTION("""COMPUTED_VALUE"""),"4A") -> 4A
A7: =IFERROR(__xludf.DUMMYFUNCTION("""COMPUTED_VALUE"""),5.0) -> 5 | B7: =IFERROR(__xludf.DUMMYFUNCTION("""COMPUTED_VALUE"""),"BANCA-BANCA, SAN FRANCISCO, SAN FELIX, SAN ROQUE IRRIGATORS ASSOCIATION, INC.") -> BANCA-BANCA, SAN FRANCISCO, SAN FELIX, SAN ROQUE IRRIGATORS ASSOCIATION, INC. | C7: =IFERROR(__xludf.DUMMYFUNCTION("""COMPUTED_VALUE"""),"SAN FRANCISCO, VICTORIA, LAGUNA") -> SAN FRANCISCO, VICTORIA, LAGUNA | D7: =IFERROR(__xludf.DUMMYFUNCTION("""COMPUTED_VALUE"""),"Francisco Gonzales") -> Francisco Gonzales | E7: =IFERROR(__xludf.DUMMYFUNCTION("""COMPUTED_VALUE"""),"0968 664 7688") -> 0968 664 7688 | F7: =IFERROR(__xludf.DUMMYFUNCTION("""COMPUTED_VALUE"""),"RCEF 23-08-20 Rebidding") -> RCEF 23-08-20 Rebidding | G7: =IFERROR(__xludf.DUMMYFUNCTION("""COMPUTED_VALUE"""),1.0) -> 1 | H7: =IFERROR(__xludf.DUMMYFUNCTION("""COMPUTED_VALUE"""),16770.0) -> 16770 | I7: =IFERROR(__xludf.DUMMYFUNCTION("""COMPUTED_VALUE"""),"KMC5825AHPFPV0010") -> KMC5825AHPFPV0010 | J7: =IFERROR(__xludf.DUMMYFUNCTION("""COMPUTED_VALUE"""),"PTS100002") -> PTS100002 | K7: =IFERROR(__xludf.DUMMYFUNCTION("""COMPUTED_VALUE"""),"R-SERIES 008 PH") -> R-SERIES 008 PH | L7: =IFERROR(__xludf.DUMMYFUNCTION("""COMPUTED_VALUE"""),"WR LSGW 0005") -> WR LSGW 0005 | M7: =IFERROR(__xludf.DUMMYFUNCTION("""COMPUTED_VALUE"""),"WR WDP 0005") -> WR WDP 0005 | O7: =IFERROR(__xludf.DUMMYFUNCTION("""COMPUTED_VALUE"""),"San Francisco") -> San Francisco | P7: =IFERROR(__xludf.DUMMYFUNCTION("""COMPUTED_VALUE"""),"Victoria") -> Victoria | Q7: =IFERROR(__xludf.DUMMYFUNCTION("""COMPUTED_VALUE"""),"Laguna") -> Laguna | R7: =IFERROR(__xludf.DUMMYFUNCTION("""COMPUTED_VALUE"""),"4A") -> 4A
A8: =IFERROR(__xludf.DUMMYFUNCTION("""COMPUTED_VALUE"""),6.0) -> 6 | B8: =IFERROR(__xludf.DUMMYFUNCTION("""COMPUTED_VALUE"""),"POBLACION-NEW DAGUPAN FARMER-IRRIGATORS' ASSOCIATION (PONDAFIA) INC.") -> POBLACION-NEW DAGUPAN FARMER-IRRIGATORS' ASSOCIATION (PONDAFIA) INC. | C8: =IFERROR(__xludf.DUMMYFUNCTION("""COMPUTED_VALUE"""),"POBLACION, CALinTAAN, OCCIDENTAL MINDORO") -> POBLACION, CALinTAAN, OCCIDENTAL MINDORO | D8: =IFERROR(__xludf.DUMMYFUNCTION("""COMPUTED_VALUE"""),"Manuel A. Francisco") -> Manuel A. Francisco | E8: =IFERROR(__xludf.DUMMYFUNCTION("""COMPUTED_VALUE"""),"0935 417 5163") -> 0935 417 5163 | F8: =IFERROR(__xludf.DUMMYFUNCTION("""COMPUTED_VALUE"""),"RCEF 23-08-20 Rebidding") -> RCEF 23-08-20 Rebidding | G8: =IFERROR(__xludf.DUMMYFUNCTION("""COMPUTED_VALUE"""),1.0) -> 1 | H8: =IFERROR(__xludf.DUMMYFUNCTION("""COMPUTED_VALUE"""),16771.0) -> 16771 | I8: =IFERROR(__xludf.DUMMYFUNCTION("""COMPUTED_VALUE"""),"KMC 5825 ACPFPV0003") -> KMC 5825 ACPFPV0003 | J8: =IFERROR(__xludf.DUMMYFUNCTION("""COMPUTED_VALUE"""),"PTS100013") -> PTS100013 | K8: =IFERROR(__xludf.DUMMYFUNCTION("""COMPUTED_VALUE"""),"R-SERIES 009 PH") -> R-SERIES 009 PH | L8: =IFERROR(__xludf.DUMMYFUNCTION("""COMPUTED_VALUE"""),"WR LSGW 0006") -> WR LSGW 0006 | M8: =IFERROR(__xludf.DUMMYFUNCTION("""COMPUTED_VALUE"""),"WR WDP 0006") -> WR WDP 0006 | O8: =IFERROR(__xludf.DUMMYFUNCTION("""COMPUTED_VALUE"""),"Poblacion") -> Poblacion | P8: =IFERROR(__xludf.DUMMYFUNCTION("""COMPUTED_VALUE"""),"Calintaan") -> Calintaan | Q8: =IFERROR(__xludf.DUMMYFUNCTION("""COMPUTED_VALUE"""),"Occidental Mindoro") -> Occidental Mindoro | R8: =IFERROR(__xludf.DUMMYFUNCTION("""COMPUTED_VALUE"""),"4B") -> 4B
A9: =IFERROR(__xludf.DUMMYFUNCTION("""COMPUTED_VALUE"""),7.0) -> 7 | B9: =IFERROR(__xludf.DUMMYFUNCTION("""COMPUTED_VALUE"""),"BUGTONG BURI FARMERS ASSOCIATION, INC.") -> BUGTONG BURI FARMERS ASSOCIATION, INC. | C9: =IFERROR(__xludf.DUMMYFUNCTION("""COMPUTED_VALUE"""),"POBLACION, MAGSAYSAY, OCCIDENTAL MINDORO") -> POBLACION, MAGSAYSAY, OCCIDENTAL MINDORO | D9: =IFERROR(__xludf.DUMMYFUNCTION("""COMPUTED_VALUE"""),"Gloria G. Operio") -> Gloria G. Operio | E9: =IFERROR(__xludf.DUMMYFUNCTION("""COMPUTED_VALUE"""),"0930 925 4686") -> 0930 925 4686 | F9: =IFERROR(__xludf.DUMMYFUNCTION("""COMPUTED_VALUE"""),"RCEF 23-08-20 Rebidding") -> RCEF 23-08-20 Rebidding | G9: =IFERROR(__xludf.DUMMYFUNCTION("""COMPUTED_VALUE"""),1.0) -> 1 | H9: =IFERROR(__xludf.DUMMYFUNCTION("""COMPUTED_VALUE"""),16772.0) -> 16772 | I9: =IFERROR(__xludf.DUMMYFUNCTION("""COMPUTED_VALUE"""),"KMC 5825 APPFPV0014") -> KMC 5825 APPFPV0014 | J9: =IFERROR(__xludf.DUMMYFUNCTION("""COMPUTED_VALUE"""),"PTS100016") -> PTS100016 | K9: =IFERROR(__xludf.DUMMYFUNCTION("""COMPUTED_VALUE"""),"R-SERIES 006 PH") -> R-SERIES 006 PH | L9: =IFERROR(__xludf.DUMMYFUNCTION("""COMPUTED_VALUE"""),"WR LSGW 0007") -> WR LSGW 0007 | M9: =IFERROR(__xludf.DUMMYFUNCTION("""COMPUTED_VALUE"""),"WR WDP 0007") -> WR WDP 0007 | O9: =IFERROR(__xludf.DUMMYFUNCTION("""COMPUTED_VALUE"""),"Poblacion") -> Poblacion | P9: =IFERROR(__xludf.DUMMYFUNCTION("""COMPUTED_VALUE"""),"Magsaysay") -> Magsaysay | Q9: =IFERROR(__xludf.DUMMYFUNCTION("""COMPUTED_VALUE"""),"Occidental Mindoro") -> Occidental Mindoro | R9: =IFERROR(__xludf.DUMMYFUNCTION("""COMPUTED_VALUE"""),"4B") -> 4B
A10: =IFERROR(__xludf.DUMMYFUNCTION("""COMPUTED_VALUE"""),8.0) -> 8 | B10: =IFERROR(__xludf.DUMMYFUNCTION("""COMPUTED_VALUE"""),"SAMARICA OCCIDENTAL MINDORO FARMERS ASSOCIATION INC.") -> SAMARICA OCCIDENTAL MINDORO FARMERS ASSOCIATION INC. | C10: =IFERROR(__xludf.DUMMYFUNCTION("""COMPUTED_VALUE"""),"ADELA, RIZAL, OCCIDENTAL MINDORO") -> ADELA, RIZAL, OCCIDENTAL MINDORO | D10: =IFERROR(__xludf.DUMMYFUNCTION("""COMPUTED_VALUE"""),"Josie M. Maramot") -> Josie M. Maramot | E10: =IFERROR(__xludf.DUMMYFUNCTION("""COMPUTED_VALUE"""),"0949 933 1443") -> 0949 933 1443 | F10: =IFERROR(__xludf.DUMMYFUNCTION("""COMPUTED_VALUE"""),"RCEF 23-08-20 Rebidding") -> RCEF 23-08-20 Rebidding | G10: =IFERROR(__xludf.DUMMYFUNCTION("""COMPUTED_VALUE"""),1.0) -> 1 | H10: =IFERROR(__xludf.DUMMYFUNCTION("""COMPUTED_VALUE"""),16774.0) -> 16774 | I10: =IFERROR(__xludf.DUMMYFUNCTION("""COMPUTED_VALUE"""),"KMC 5825 AVPFPV0004") -> KMC 5825 AVPFPV0004 | J10: =IFERROR(__xludf.DUMMYFUNCTION("""COMPUTED_VALUE"""),"PTS100020") -> PTS100020 | K10: =IFERROR(__xludf.DUMMYFUNCTION("""COMPUTED_VALUE"""),"R-SERIES 018 PH") -> R-SERIES 018 PH | L10: =IFERROR(__xludf.DUMMYFUNCTION("""COMPUTED_VALUE"""),"WR LSGW 0009") -> WR LSGW 0009 | M10: =IFERROR(__xludf.DUMMYFUNCTION("""COMPUTED_VALUE"""),"WR WDP 0009") -> WR WDP 0009 | O10: =IFERROR(__xludf.DUMMYFUNCTION("""COMPUTED_VALUE"""),"Adela") -> Adela | P10: =IFERROR(__xludf.DUMMYFUNCTION("""COMPUTED_VALUE"""),"Rizal") -> Rizal | Q10: =IFERROR(__xludf.DUMMYFUNCTION("""COMPUTED_VALUE"""),"Occidental Mindoro") -> Occidental Mindoro | R10: =IFERROR(__xludf.DUMMYFUNCTION("""COMPUTED_VALUE"""),"4B") -> 4B
A11: =IFERROR(__xludf.DUMMYFUNCTION("""COMPUTED_VALUE"""),9.0) -> 9 | B11: =IFERROR(__xludf.DUMMYFUNCTION("""COMPUTED_VALUE"""),"SALVACION UNITED FARMERS MULTI-PURPOSE COOPERATIVE") -> SALVACION UNITED FARMERS MULTI-PURPOSE COOPERATIVE | C11: =IFERROR(__xludf.DUMMYFUNCTION("""COMPUTED_VALUE"""),"SALVACION, RIZAL, OCCIDENTAL MINDORO") -> SALVACION, RIZAL, OCCIDENTAL MINDORO | D11: =IFERROR(__xludf.DUMMYFUNCTION("""COMPUTED_VALUE"""),"Birtsan A. Montales") -> Birtsan A. Montales | E11: =IFERROR(__xludf.DUMMYFUNCTION("""COMPUTED_VALUE"""),"0930 838 7003") -> 0930 838 7003 | F11: =IFERROR(__xludf.DUMMYFUNCTION("""COMPUTED_VALUE"""),"RCEF 23-08-20 Rebidding") -> RCEF 23-08-20 Rebidding | G11: =IFERROR(__xludf.DUMMYFUNCTION("""COMPUTED_VALUE"""),1.0) -> 1 | H11: =IFERROR(__xludf.DUMMYFUNCTION("""COMPUTED_VALUE"""),16775.0) -> 16775 | I11: =IFERROR(__xludf.DUMMYFUNCTION("""COMPUTED_VALUE"""),"KMC 5825 AJPFPV0033") -> KMC 5825 AJPFPV0033 | J11: =IFERROR(__xludf.DUMMYFUNCTION("""COMPUTED_VALUE"""),"PTS100031") -> PTS100031 | K11: =IFERROR(__xludf.DUMMYFUNCTION("""COMPUTED_VALUE"""),"R-SERIES 023 PH") -> R-SERIES 023 PH | L11: =IFERROR(__xludf.DUMMYFUNCTION("""COMPUTED_VALUE"""),"WR LSGW 0010") -> WR LSGW 0010 | M11: =IFERROR(__xludf.DUMMYFUNCTION("""COMPUTED_VALUE"""),"WR WDP 0010") -> WR WDP 0010 | O11: =IFERROR(__xludf.DUMMYFUNCTION("""COMPUTED_VALUE"""),"Salvacion") -> Salvacion | P11: =IFERROR(__xludf.DUMMYFUNCTION("""COMPUTED_VALUE"""),"Rizal") -> Rizal | Q11: =IFERROR(__xludf.DUMMYFUNCTION("""COMPUTED_VALUE"""),"Occidental Mindoro") -> Occidental Mindoro | R11: =IFERROR(__xludf.DUMMYFUNCTION("""COMPUTED_VALUE"""),"4B") -> 4B
A12: =IFERROR(__xludf.DUMMYFUNCTION("""COMPUTED_VALUE"""),10.0) -> 10 | B12: =IFERROR(__xludf.DUMMYFUNCTION("""COMPUTED_VALUE"""),"MATABIAGA MALAWAAN IRRIGATORS ASSOCIATION, INC.") -> MATABIAGA MALAWAAN IRRIGATORS ASSOCIATION, INC. | C12: =IFERROR(__xludf.DUMMYFUNCTION("""COMPUTED_VALUE"""),"MALAWAAN, RIZAL, OCCIDENTAL MINDORO") -> MALAWAAN, RIZAL, OCCIDENTAL MINDORO | D12: =IFERROR(__xludf.DUMMYFUNCTION("""COMPUTED_VALUE"""),"Ernie Urbina") -> Ernie Urbina | E12: =IFERROR(__xludf.DUMMYFUNCTION("""COMPUTED_VALUE"""),"0909 354 0587") -> 0909 354 0587 | F12: =IFERROR(__xludf.DUMMYFUNCTION("""COMPUTED_VALUE"""),"RCEF 23-08-20 Rebidding") -> RCEF 23-08-20 Rebidding | G12: =IFERROR(__xludf.DUMMYFUNCTION("""COMPUTED_VALUE"""),1.0) -> 1 | H12: =IFERROR(__xludf.DUMMYFUNCTION("""COMPUTED_VALUE"""),16776.0) -> 16776 | I12: =IFERROR(__xludf.DUMMYFUNCTION("""COMPUTED_VALUE"""),"KMC 5825 AEPFPV0008") -> KMC 5825 AEPFPV0008 | J12: =IFERROR(__xludf.DUMMYFUNCTION("""COMPUTED_VALUE"""),"PTS100005") -> PTS100005 | K12: =IFERROR(__xludf.DUMMYFUNCTION("""COMPUTED_VALUE"""),"R-SERIES 015 PH") -> R-SERIES 015 PH | L12: =IFERROR(__xludf.DUMMYFUNCTION("""COMPUTED_VALUE"""),"WR LSGW 0011") -> WR LSGW 0011 | M12: =IFERROR(__xludf.DUMMYFUNCTION("""COMPUTED_VALUE"""),"WR WDP 0011") -> WR WDP 0011 | O12: =IFERROR(__xludf.DUMMYFUNCTION("""COMPUTED_VALUE"""),"Malawaan") -> Malawaan | P12: =IFERROR(__xludf.DUMMYFUNCTION("""COMPUTED_VALUE"""),"Rizal") -> Rizal | Q12: =IFERROR(__xludf.DUMMYFUNCTION("""COMPUTED_VALUE"""),"Occidental Mindoro") -> Occidental Mindoro | R12: =IFERROR(__xludf.DUMMYFUNCTION("""COMPUTED_VALUE"""),"4B") -> 4B
A13: =IFERROR(__xludf.DUMMYFUNCTION("""COMPUTED_VALUE"""),11.0) -> 11 | B13: =IFERROR(__xludf.DUMMYFUNCTION("""COMPUTED_VALUE"""),"BARANGAY BATONG BUHAY FARMER'S ASSOCIATION") -> BARANGAY BATONG BUHAY FARMER'S ASSOCIATION | C13: =IFERROR(__xludf.DUMMYFUNCTION("""COMPUTED_VALUE"""),"BATONG BUHAY, SABLAYAN, OCCIDENTAL MINDORO") -> BATONG BUHAY, SABLAYAN, OCCIDENTAL MINDORO | D13: =IFERROR(__xludf.DUMMYFUNCTION("""COMPUTED_VALUE"""),"Mark Anthony Silao") -> Mark Anthony Silao | E13: =IFERROR(__xludf.DUMMYFUNCTION("""COMPUTED_VALUE"""),"0966 359 5285") -> 0966 359 5285 | F13: =IFERROR(__xludf.DUMMYFUNCTION("""COMPUTED_VALUE"""),"RCEF 23-08-20 Rebidding") -> RCEF 23-08-20 Rebidding | G13: =IFERROR(__xludf.DUMMYFUNCTION("""COMPUTED_VALUE"""),1.0) -> 1 | H13: =IFERROR(__xludf.DUMMYFUNCTION("""COMPUTED_VALUE"""),16777.0) -> 16777 | I13: =IFERROR(__xludf.DUMMYFUNCTION("""COMPUTED_VALUE"""),"KMC 5825 ATPFPV0013") -> KMC 5825 ATPFPV0013 | J13: =IFERROR(__xludf.DUMMYFUNCTION("""COMPUTED_VALUE"""),"PTS100027") -> PTS100027 | K13: =IFERROR(__xludf.DUMMYFUNCTION("""COMPUTED_VALUE"""),"R-SERIES 022 PH") -> R-SERIES 022 PH | L13: =IFERROR(__xludf.DUMMYFUNCTION("""COMPUTED_VALUE"""),"WR LSGW 0012") -> WR LSGW 0012 | M13: =IFERROR(__xludf.DUMMYFUNCTION("""COMPUTED_VALUE"""),"WR WDP 0012") -> WR WDP 0012 | O13: =IFERROR(__xludf.DUMMYFUNCTION("""COMPUTED_VALUE"""),"Batong Buhay") -> Batong Buhay | P13: =IFERROR(__xludf.DUMMYFUNCTION("""COMPUTED_VALUE"""),"Sablayan") -> Sablayan | Q13: =IFERROR(__xludf.DUMMYFUNCTION("""COMPUTED_VALUE"""),"Occidental Mindoro") -> Occidental Mindoro | R13: =IFERROR(__xludf.DUMMYFUNCTION("""COMPUTED_VALUE"""),"4B") -> 4B
A14: =IFERROR(__xludf.DUMMYFUNCTION("""COMPUTED_VALUE"""),12.0) -> 12 | B14: =IFERROR(__xludf.DUMMYFUNCTION("""COMPUTED_VALUE"""),"KAINGIN TAGUMPAY FARMERS AND IRRIGATORS ASSOCIATION (KATFAIA)") -> KAINGIN TAGUMPAY FARMERS AND IRRIGATORS ASSOCIATION (KATFAIA) | C14: =IFERROR(__xludf.DUMMYFUNCTION("""COMPUTED_VALUE"""),"TAGUMPAY, SABLAYAN, OCCIDENTAL MINDORO") -> TAGUMPAY, SABLAYAN, OCCIDENTAL MINDORO | D14: =IFERROR(__xludf.DUMMYFUNCTION("""COMPUTED_VALUE"""),"Robert Navalta") -> Robert Navalta | E14: =IFERROR(__xludf.DUMMYFUNCTION("""COMPUTED_VALUE"""),"0975 537 0138") -> 0975 537 0138 | F14: =IFERROR(__xludf.DUMMYFUNCTION("""COMPUTED_VALUE"""),"RCEF 23-08-20 Rebidding") -> RCEF 23-08-20 Rebidding | G14: =IFERROR(__xludf.DUMMYFUNCTION("""COMPUTED_VALUE"""),1.0) -> 1 | H14: =IFERROR(__xludf.DUMMYFUNCTION("""COMPUTED_VALUE"""),16778.0) -> 16778 | I14: =IFERROR(__xludf.DUMMYFUNCTION("""COMPUTED_VALUE"""),"KMC 5825 AVPFPV0021") -> KMC 5825 AVPFPV0021 | J14: =IFERROR(__xludf.DUMMYFUNCTION("""COMPUTED_VALUE"""),"PTS100025") -> PTS100025 | K14: =IFERROR(__xludf.DUMMYFUNCTION("""COMPUTED_VALUE"""),"R-SERIES016 PH") -> R-SERIES016 PH | L14: =IFERROR(__xludf.DUMMYFUNCTION("""COMPUTED_VALUE"""),"WR LSGW 0013") -> WR LSGW 0013 | M14: =IFERROR(__xludf.DUMMYFUNCTION("""COMPUTED_VALUE"""),"WR WDP 0013") -> WR WDP 0013 | O14: =IFERROR(__xludf.DUMMYFUNCTION("""COMPUTED_VALUE"""),"Tagumpay") -> Tagumpay | P14: =IFERROR(__xludf.DUMMYFUNCTION("""COMPUTED_VALUE"""),"Sablayan") -> Sablayan | Q14: =IFERROR(__xludf.DUMMYFUNCTION("""COMPUTED_VALUE"""),"Occidental Mindoro") -> Occidental Mindoro | R14: =IFERROR(__xludf.DUMMYFUNCTION("""COMPUTED_VALUE"""),"4B") -> 4B
A15: =IFERROR(__xludf.DUMMYFUNCTION("""COMPUTED_VALUE"""),13.0) -> 13 | B15: =IFERROR(__xludf.DUMMYFUNCTION("""COMPUTED_VALUE"""),"SITIO ESPERANZA SAN ISIDRO FARMERS ASSOCIATION") -> SITIO ESPERANZA SAN ISIDRO FARMERS ASSOCIATION | C15: =IFERROR(__xludf.DUMMYFUNCTION("""COMPUTED_VALUE"""),"SAN ISIDRO, SAN JOSE, OCCIDENTAL MINDORO") -> SAN ISIDRO, SAN JOSE, OCCIDENTAL MINDORO | D15: =IFERROR(__xludf.DUMMYFUNCTION("""COMPUTED_VALUE"""),"Catalina Monterola") -> Catalina Monterola | E15: =IFERROR(__xludf.DUMMYFUNCTION("""COMPUTED_VALUE"""),"0929 367 9563") -> 0929 367 9563 | F15: =IFERROR(__xludf.DUMMYFUNCTION("""COMPUTED_VALUE"""),"RCEF 23-08-20 Rebidding") -> RCEF 23-08-20 Rebidding | G15: =IFERROR(__xludf.DUMMYFUNCTION("""COMPUTED_VALUE"""),1.0) -> 1 | H15: =IFERROR(__xludf.DUMMYFUNCTION("""COMPUTED_VALUE"""),16779.0) -> 16779 | I15: =IFERROR(__xludf.DUMMYFUNCTION("""COMPUTED_VALUE"""),"KMC 5825 ALPFPV0023") -> KMC 5825 ALPFPV0023 | J15: =IFERROR(__xludf.DUMMYFUNCTION("""COMPUTED_VALUE"""),"PTS100010") -> PTS100010 | K15: =IFERROR(__xludf.DUMMYFUNCTION("""COMPUTED_VALUE"""),"R-SERIES 013 PH") -> R-SERIES 013 PH | L15: =IFERROR(__xludf.DUMMYFUNCTION("""COMPUTED_VALUE"""),"WR LSGW 0014") -> WR LSGW 0014 | M15: =IFERROR(__xludf.DUMMYFUNCTION("""COMPUTED_VALUE"""),"WR WDP 0014") -> WR WDP 0014 | O15: =IFERROR(__xludf.DUMMYFUNCTION("""COMPUTED_VALUE"""),"San Isidro") -> San Isidro | P15: =IFERROR(__xludf.DUMMYFUNCTION("""COMPUTED_VALUE"""),"San Jose") -> San Jose | Q15: =IFERROR(__xludf.DUMMYFUNCTION("""COMPUTED_VALUE"""),"Occidental Mindoro") -> Occidental Mindoro | R15: =IFERROR(__xludf.DUMMYFUNCTION("""COMPUTED_VALUE"""),"4B") -> 4B
A16: =IFERROR(__xludf.DUMMYFUNCTION("""COMPUTED_VALUE"""),14.0) -> 14 | B16: =IFERROR(__xludf.DUMMYFUNCTION("""COMPUTED_VALUE"""),"CAMANDANG IRRIGATORS ASSOCIATION") -> CAMANDANG IRRIGATORS ASSOCIATION | C16: =IFERROR(__xludf.DUMMYFUNCTION("""COMPUTED_VALUE"""),"MONTECLARO, SAN JOSE, OCCIDENTAL MINDORO") -> MONTECLARO, SAN JOSE, OCCIDENTAL MINDORO | D16: =IFERROR(__xludf.DUMMYFUNCTION("""COMPUTED_VALUE"""),"Eduardo Toquero Jr.") -> Eduardo Toquero Jr. | E16: =IFERROR(__xludf.DUMMYFUNCTION("""COMPUTED_VALUE"""),"0965 897 7577") -> 0965 897 7577 | F16: =IFERROR(__xludf.DUMMYFUNCTION("""COMPUTED_VALUE"""),"RCEF 23-08-20 Rebidding") -> RCEF 23-08-20 Rebidding | G16: =IFERROR(__xludf.DUMMYFUNCTION("""COMPUTED_VALUE"""),1.0) -> 1 | H16: =IFERROR(__xludf.DUMMYFUNCTION("""COMPUTED_VALUE"""),16780.0) -> 16780 | I16: =IFERROR(__xludf.DUMMYFUNCTION("""COMPUTED_VALUE"""),"KMC 5825 ATPFPV0030") -> KMC 5825 ATPFPV0030 | J16: =IFERROR(__xludf.DUMMYFUNCTION("""COMPUTED_VALUE"""),"PTS100014") -> PTS100014 | K16: =IFERROR(__xludf.DUMMYFUNCTION("""COMPUTED_VALUE"""),"R-SERIES 024 PH") -> R-SERIES 024 PH | L16: =IFERROR(__xludf.DUMMYFUNCTION("""COMPUTED_VALUE"""),"WR LSGW 0015") -> WR LSGW 0015 | M16: =IFERROR(__xludf.DUMMYFUNCTION("""COMPUTED_VALUE"""),"WR WDP 0015") -> WR WDP 0015 | O16: =IFERROR(__xludf.DUMMYFUNCTION("""COMPUTED_VALUE"""),"Monteclaro") -> Monteclaro | P16: =IFERROR(__xludf.DUMMYFUNCTION("""COMPUTED_VALUE"""),"San Jose") -> San Jose | Q16: =IFERROR(__xludf.DUMMYFUNCTION("""COMPUTED_VALUE"""),"Occidental Mindoro") -> Occidental Mindoro | R16: =IFERROR(__xludf.DUMMYFUNCTION("""COMPUTED_VALUE"""),"4B") -> 4B
A17: =IFERROR(__xludf.DUMMYFUNCTION("""COMPUTED_VALUE"""),15.0) -> 15 | B17: =IFERROR(__xludf.DUMMYFUNCTION("""COMPUTED_VALUE"""),"SAMAHAN NG MAGSASAKA SA PALANGHIRAN") -> SAMAHAN NG MAGSASAKA SA PALANGHIRAN | C17: =IFERROR(__xludf.DUMMYFUNCTION("""COMPUTED_VALUE"""),"MAPAYA, SAN JOSE, OCCIDENTAL MINDORO") -> MAPAYA, SAN JOSE, OCCIDENTAL MINDORO | D17: =IFERROR(__xludf.DUMMYFUNCTION("""COMPUTED_VALUE"""),"Ricardo E. Dela Cruz") -> Ricardo E. Dela Cruz | E17: =IFERROR(__xludf.DUMMYFUNCTION("""COMPUTED_VALUE"""),"0912 631 8700") -> 0912 631 8700 | F17: =IFERROR(__xludf.DUMMYFUNCTION("""COMPUTED_VALUE"""),"RCEF 23-08-20 Rebidding") -> RCEF 23-08-20 Rebidding | G17: =IFERROR(__xludf.DUMMYFUNCTION("""COMPUTED_VALUE"""),1.0) -> 1 | H17: =IFERROR(__xludf.DUMMYFUNCTION("""COMPUTED_VALUE"""),16781.0) -> 16781 | I17: =IFERROR(__xludf.DUMMYFUNCTION("""COMPUTED_VALUE"""),"KMC 5825 AKPFPV0032") -> KMC 5825 AKPFPV0032 | J17: =IFERROR(__xludf.DUMMYFUNCTION("""COMPUTED_VALUE"""),"PTS100039") -> PTS100039 | K17: =IFERROR(__xludf.DUMMYFUNCTION("""COMPUTED_VALUE"""),"R-SERIES 007 PH") -> R-SERIES 007 PH | L17: =IFERROR(__xludf.DUMMYFUNCTION("""COMPUTED_VALUE"""),"WR LSGW 0016") -> WR LSGW 0016 | M17: =IFERROR(__xludf.DUMMYFUNCTION("""COMPUTED_VALUE"""),"WR WDP 0016") -> WR WDP 0016 | O17: =IFERROR(__xludf.DUMMYFUNCTION("""COMPUTED_VALUE"""),"Mapaya") -> Mapaya | P17: =IFERROR(__xludf.DUMMYFUNCTION("""COMPUTED_VALUE"""),"San Jose") -> San Jose | Q17: =IFERROR(__xludf.DUMMYFUNCTION("""COMPUTED_VALUE"""),"Occidental Mindoro") -> Occidental Mindoro | R17: =IFERROR(__xludf.DUMMYFUNCTION("""COMPUTED_VALUE"""),"4B") -> 4B
A18: =IFERROR(__xludf.DUMMYFUNCTION("""COMPUTED_VALUE"""),16.0) -> 16 | B18: =IFERROR(__xludf.DUMMYFUNCTION("""COMPUTED_VALUE"""),"NAGKAKAISANG LAKAS MULTI-PURPOSE COOPERATIVE") -> NAGKAKAISANG LAKAS MULTI-PURPOSE COOPERATIVE | C18: =IFERROR(__xludf.DUMMYFUNCTION("""COMPUTED_VALUE"""),"LABANGAN POBLACION, SAN JOSE, OCCIDENTAL MINDORO") -> LABANGAN POBLACION, SAN JOSE, OCCIDENTAL MINDORO | D18: =IFERROR(__xludf.DUMMYFUNCTION("""COMPUTED_VALUE"""),"Josephine Mallari") -> Josephine Mallari | E18: =IFERROR(__xludf.DUMMYFUNCTION("""COMPUTED_VALUE"""),"(0917) 839 4280") -> (0917) 839 4280 | F18: =IFERROR(__xludf.DUMMYFUNCTION("""COMPUTED_VALUE"""),"RCEF 23-08-20 Rebidding") -> RCEF 23-08-20 Rebidding | G18: =IFERROR(__xludf.DUMMYFUNCTION("""COMPUTED_VALUE"""),1.0) -> 1 | H18: =IFERROR(__xludf.DUMMYFUNCTION("""COMPUTED_VALUE"""),16782.0) -> 16782 | I18: =IFERROR(__xludf.DUMMYFUNCTION("""COMPUTED_VALUE"""),"KMC 5825 AKPFPV0029") -> KMC 5825 AKPFPV0029 | J18: =IFERROR(__xludf.DUMMYFUNCTION("""COMPUTED_VALUE"""),"PTS100022") -> PTS100022 | K18: =IFERROR(__xludf.DUMMYFUNCTION("""COMPUTED_VALUE"""),"R-SERIES 025 PH") -> R-SERIES 025 PH | L18: =IFERROR(__xludf.DUMMYFUNCTION("""COMPUTED_VALUE"""),"WR LSGW 0017") -> WR LSGW 0017 | M18: =IFERROR(__xludf.DUMMYFUNCTION("""COMPUTED_VALUE"""),"WR WDP 0017") -> WR WDP 0017 | O18: =IFERROR(__xludf.DUMMYFUNCTION("""COMPUTED_VALUE"""),"Labangan Poblacion") -> Labangan Poblacion | P18: =IFERROR(__xludf.DUMMYFUNCTION("""COMPUTED_VALUE"""),"San Jose") -> San Jose | Q18: =IFERROR(__xludf.DUMMYFUNCTION("""COMPUTED_VALUE"""),"Occidental Mindoro") -> Occidental Mindoro | R18: =IFERROR(__xludf.DUMMYFUNCTION("""COMPUTED_VALUE"""),"4B") -> 4B
A19: =IFERROR(__xludf.DUMMYFUNCTION("""COMPUTED_VALUE"""),17.0) -> 17 | B19: =IFERROR(__xludf.DUMMYFUNCTION("""COMPUTED_VALUE"""),"GINTONG BUTIL FARMERS ASSOCIATION") -> GINTONG BUTIL FARMERS ASSOCIATION | C19: =IFERROR(__xludf.DUMMYFUNCTION("""COMPUTED_VALUE"""),"PINAGTURIHAN, SANTA CRUZ, OCCIDENTAL MINDORO") -> PINAGTURIHAN, SANTA CRUZ, OCCIDENTAL MINDORO | D19: =IFERROR(__xludf.DUMMYFUNCTION("""COMPUTED_VALUE"""),"Rodolfo Patal, Jr.") -> Rodolfo Patal, Jr. | E19: =IFERROR(__xludf.DUMMYFUNCTION("""COMPUTED_VALUE"""),"0935-879-0354") -> 0935-879-0354 | F19: =IFERROR(__xludf.DUMMYFUNCTION("""COMPUTED_VALUE"""),"RCEF 23-08-20 Rebidding") -> RCEF 23-08-20 Rebidding | G19: =IFERROR(__xludf.DUMMYFUNCTION("""COMPUTED_VALUE"""),1.0) -> 1 | H19: =IFERROR(__xludf.DUMMYFUNCTION("""COMPUTED_VALUE"""),16783.0) -> 16783 | I19: =IFERROR(__xludf.DUMMYFUNCTION("""COMPUTED_VALUE"""),"KMC 5825 AEPFPV0019") -> KMC 5825 AEPFPV0019 | J19: =IFERROR(__xludf.DUMMYFUNCTION("""COMPUTED_VALUE"""),"PTS100040") -> PTS100040 | K19: =IFERROR(__xludf.DUMMYFUNCTION("""COMPUTED_VALUE"""),"R-SERIES 011 PH") -> R-SERIES 011 PH | L19: =IFERROR(__xludf.DUMMYFUNCTION("""COMPUTED_VALUE"""),"WR LSGW 0018") -> WR LSGW 0018 | M19: =IFERROR(__xludf.DUMMYFUNCTION("""COMPUTED_VALUE"""),"WR WDP 0018") -> WR WDP 0018 | O19: =IFERROR(__xludf.DUMMYFUNCTION("""COMPUTED_VALUE"""),"Pinagturihan") -> Pinagturihan | P19: =IFERROR(__xludf.DUMMYFUNCTION("""COMPUTED_VALUE"""),"Santa Cruz") -> Santa Cruz | Q19: =IFERROR(__xludf.DUMMYFUNCTION("""COMPUTED_VALUE"""),"Occidental Mindoro") -> Occidental Mindoro | R19: =IFERROR(__xludf.DUMMYFUNCTION("""COMPUTED_VALUE"""),"4B") -> 4B
A20: =IFERROR(__xludf.DUMMYFUNCTION("""COMPUTED_VALUE"""),18.0) -> 18 | B20: =IFERROR(__xludf.DUMMYFUNCTION("""COMPUTED_VALUE"""),"MUNICIPAL LOCAL GOVERNMENT UNIT OF RIZAL") -> MUNICIPAL LOCAL GOVERNMENT UNIT OF RIZAL | C20: =IFERROR(__xludf.DUMMYFUNCTION("""COMPUTED_VALUE"""),"RUMBANG, RIZAL, OCCIDENTAL MINDORO") -> RUMBANG, RIZAL, OCCIDENTAL MINDORO | D20: =IFERROR(__xludf.DUMMYFUNCTION("""COMPUTED_VALUE"""),"#N/A") -> #N/A | E20: =IFERROR(__xludf.DUMMYFUNCTION("""COMPUTED_VALUE"""),"#N/A") -> #N/A | F20: =IFERROR(__xludf.DUMMYFUNCTION("""COMPUTED_VALUE"""),"RCEF 23-08-20 Rebidding") -> RCEF 23-08-20 Rebidding | G20: =IFERROR(__xludf.DUMMYFUNCTION("""COMPUTED_VALUE"""),1.0) -> 1 | H20: =IFERROR(__xludf.DUMMYFUNCTION("""COMPUTED_VALUE"""),16786.0) -> 16786 | I20: =IFERROR(__xludf.DUMMYFUNCTION("""COMPUTED_VALUE"""),"KMC 5825 AJPFPV0002") -> KMC 5825 AJPFPV0002 | J20: =IFERROR(__xludf.DUMMYFUNCTION("""COMPUTED_VALUE"""),"PTS100018") -> PTS100018 | K20: =IFERROR(__xludf.DUMMYFUNCTION("""COMPUTED_VALUE"""),"R-SERIES 003 PH") -> R-SERIES 003 PH | L20: =IFERROR(__xludf.DUMMYFUNCTION("""COMPUTED_VALUE"""),"WR LSGW 0008") -> WR LSGW 0008 | M20: =IFERROR(__xludf.DUMMYFUNCTION("""COMPUTED_VALUE"""),"WR WDP 0008") -> WR WDP 0008 | O20: =IFERROR(__xludf.DUMMYFUNCTION("""COMPUTED_VALUE"""),"Rumbang") -> Rumbang | P20: =IFERROR(__xludf.DUMMYFUNCTION("""COMPUTED_VALUE"""),"Rizal") -> Rizal | Q20: =IFERROR(__xludf.DUMMYFUNCTION("""COMPUTED_VALUE"""),"Occidental Mindoro") -> Occidental Mindoro | R20: =IFERROR(__xludf.DUMMYFUNCTION("""COMPUTED_VALUE"""),"4B") -> 4B
A21: =IFERROR(__xludf.DUMMYFUNCTION("""COMPUTED_VALUE"""),19.0) -> 19 | B21: =IFERROR(__xludf.DUMMYFUNCTION("""COMPUTED_VALUE"""),"MALAPAD FARMERS ASSOCIATION") -> MALAPAD FARMERS ASSOCIATION | C21: =IFERROR(__xludf.DUMMYFUNCTION("""COMPUTED_VALUE"""),"Malapad, Baco, Oriental Mindoro") -> Malapad, Baco, Oriental Mindoro | D21: =IFERROR(__xludf.DUMMYFUNCTION("""COMPUTED_VALUE"""),"ROLANDO MANDITA") -> ROLANDO MANDITA | E21: =IFERROR(__xludf.DUMMYFUNCTION("""COMPUTED_VALUE"""),"0955 378 7221") -> 0955 378 7221 | F21: =IFERROR(__xludf.DUMMYFUNCTION("""COMPUTED_VALUE"""),"RCEF 23-08-20 Rebidding") -> RCEF 23-08-20 Rebidding | G21: =IFERROR(__xludf.DUMMYFUNCTION("""COMPUTED_VALUE"""),1.0) -> 1 | H21: =IFERROR(__xludf.DUMMYFUNCTION("""COMPUTED_VALUE"""),17379.0) -> 17379 | I21: =IFERROR(__xludf.DUMMYFUNCTION("""COMPUTED_VALUE"""),"KMC 5825 AAPFPV0005") -> KMC 5825 AAPFPV0005 | J21: =IFERROR(__xludf.DUMMYFUNCTION("""COMPUTED_VALUE"""),"PTS100012") -> PTS100012 | K21: =IFERROR(__xludf.DUMMYFUNCTION("""COMPUTED_VALUE"""),"R-SERIES 028 PH") -> R-SERIES 028 PH | L21: =IFERROR(__xludf.DUMMYFUNCTION("""COMPUTED_VALUE"""),"LSGW1750-RMP-2312036") -> LSGW1750-RMP-2312036 | M21: =IFERROR(__xludf.DUMMYFUNCTION("""COMPUTED_VALUE"""),"WDP40-RMP-2312069") -> WDP40-RMP-2312069 | O21: =IFERROR(__xludf.DUMMYFUNCTION("""COMPUTED_VALUE"""),"Malapad") -> Malapad | P21: =IFERROR(__xludf.DUMMYFUNCTION("""COMPUTED_VALUE"""),"Baco") -> Baco | Q21: =IFERROR(__xludf.DUMMYFUNCTION("""COMPUTED_VALUE"""),"Oriental Mindoro") -> Oriental Mindoro | R21: =IFERROR(__xludf.DUMMYFUNCTION("""COMPUTED_VALUE"""),"4B") -> 4B
A22: =IFERROR(__xludf.DUMMYFUNCTION("""COMPUTED_VALUE"""),20.0) -> 20 | B22: =IFERROR(__xludf.DUMMYFUNCTION("""COMPUTED_VALUE"""),"SAMAHAN NG MGA MAGSASAKA NG BARANGAY BAYANAN II") -> SAMAHAN NG MGA MAGSASAKA NG BARANGAY BAYANAN II | C22: =IFERROR(__xludf.DUMMYFUNCTION("""COMPUTED_VALUE"""),"Bayanan II, Calapan City, Oriental Mindoro") -> Bayanan II, Calapan City, Oriental Mindoro | D22: =IFERROR(__xludf.DUMMYFUNCTION("""COMPUTED_VALUE"""),"EDGAR C. BALMES") -> EDGAR C. BALMES | E22: =IFERROR(__xludf.DUMMYFUNCTION("""COMPUTED_VALUE"""),"0936 940 1320") -> 0936 940 1320 | F22: =IFERROR(__xludf.DUMMYFUNCTION("""COMPUTED_VALUE"""),"RCEF 23-08-20 Rebidding") -> RCEF 23-08-20 Rebidding | G22: =IFERROR(__xludf.DUMMYFUNCTION("""COMPUTED_VALUE"""),1.0) -> 1 | H22: =IFERROR(__xludf.DUMMYFUNCTION("""COMPUTED_VALUE"""),17380.0) -> 17380 | I22: =IFERROR(__xludf.DUMMYFUNCTION("""COMPUTED_VALUE"""),"KMC 5825 AVPFPV0035") -> KMC 5825 AVPFPV0035 | J22: =IFERROR(__xludf.DUMMYFUNCTION("""COMPUTED_VALUE"""),"PTS100034") -> PTS100034 | K22: =IFERROR(__xludf.DUMMYFUNCTION("""COMPUTED_VALUE"""),"R-SERIES 013 PH") -> R-SERIES 013 PH | L22: =IFERROR(__xludf.DUMMYFUNCTION("""COMPUTED_VALUE"""),"LSGW1750-RMP-2312024") -> LSGW1750-RMP-2312024 | M22: =IFERROR(__xludf.DUMMYFUNCTION("""COMPUTED_VALUE"""),"WDP40-RMP-2312072") -> WDP40-RMP-2312072 | O22: =IFERROR(__xludf.DUMMYFUNCTION("""COMPUTED_VALUE"""),"Bayanan Ii") -> Bayanan Ii | P22: =IFERROR(__xludf.DUMMYFUNCTION("""COMPUTED_VALUE"""),"Calapan City") -> Calapan City | Q22: =IFERROR(__xludf.DUMMYFUNCTION("""COMPUTED_VALUE"""),"Oriental Mindoro") -> Oriental Mindoro | R22: =IFERROR(__xludf.DUMMYFUNCTION("""COMPUTED_VALUE"""),"4B") -> 4B
A23: =IFERROR(__xludf.DUMMYFUNCTION("""COMPUTED_VALUE"""),21.0) -> 21 | B23: =IFERROR(__xludf.DUMMYFUNCTION("""COMPUTED_VALUE"""),"GULOD FARMERS ASSOCIATION") -> GULOD FARMERS ASSOCIATION | C23: =IFERROR(__xludf.DUMMYFUNCTION("""COMPUTED_VALUE"""),"Gulod, Calapan City, Oriental Mindoro") -> Gulod, Calapan City, Oriental Mindoro | D23: =IFERROR(__xludf.DUMMYFUNCTION("""COMPUTED_VALUE"""),"CELEDONIO GONZALES") -> CELEDONIO GONZALES | E23: =IFERROR(__xludf.DUMMYFUNCTION("""COMPUTED_VALUE"""),"0960 919 4546 0915 389 7698") -> 0960 919 4546 0915 389 7698 | F23: =IFERROR(__xludf.DUMMYFUNCTION("""COMPUTED_VALUE"""),"RCEF 23-08-20 Rebidding") -> RCEF 23-08-20 Rebidding | G23: =IFERROR(__xludf.DUMMYFUNCTION("""COMPUTED_VALUE"""),1.0) -> 1 | H23: =IFERROR(__xludf.DUMMYFUNCTION("""COMPUTED_VALUE"""),17381.0) -> 17381 | I23: =IFERROR(__xludf.DUMMYFUNCTION("""COMPUTED_VALUE"""),"KMC 5825 ACPFPV0009") -> KMC 5825 ACPFPV0009 | J23: =IFERROR(__xludf.DUMMYFUNCTION("""COMPUTED_VALUE"""),"PTS100006") -> PTS100006 | K23: =IFERROR(__xludf.DUMMYFUNCTION("""COMPUTED_VALUE"""),"R-SERIES 042 PH") -> R-SERIES 042 PH | L23: =IFERROR(__xludf.DUMMYFUNCTION("""COMPUTED_VALUE"""),"LSGW1750-RMP-2312016") -> LSGW1750-RMP-2312016 | M23: =IFERROR(__xludf.DUMMYFUNCTION("""COMPUTED_VALUE"""),"WDP40-RMP-2312053") -> WDP40-RMP-2312053 | O23: =IFERROR(__xludf.DUMMYFUNCTION("""COMPUTED_VALUE"""),"Gulod") -> Gulod | P23: =IFERROR(__xludf.DUMMYFUNCTION("""COMPUTED_VALUE"""),"Calapan City") -> Calapan City | Q23: =IFERROR(__xludf.DUMMYFUNCTION("""COMPUTED_VALUE"""),"Oriental Mindoro") -> Oriental Mindoro | R23: =IFERROR(__xludf.DUMMYFUNCTION("""COMPUTED_VALUE"""),"4B") -> 4B
A24: =IFERROR(__xludf.DUMMYFUNCTION("""COMPUTED_VALUE"""),22.0) -> 22 | B24: =IFERROR(__xludf.DUMMYFUNCTION("""COMPUTED_VALUE"""),"BALINGAYAN FARMERS ASSOCIATION") -> BALINGAYAN FARMERS ASSOCIATION | C24: =IFERROR(__xludf.DUMMYFUNCTION("""COMPUTED_VALUE"""),"Balingayan, Calapan City, Oriental Mindoro") -> Balingayan, Calapan City, Oriental Mindoro | D24: =IFERROR(__xludf.DUMMYFUNCTION("""COMPUTED_VALUE"""),"C ROBERTO S. BRUCAL") -> C ROBERTO S. BRUCAL | E24: =IFERROR(__xludf.DUMMYFUNCTION("""COMPUTED_VALUE"""),"0917 270 7772 0968 622 4404") -> 0917 270 7772 0968 622 4404 | F24: =IFERROR(__xludf.DUMMYFUNCTION("""COMPUTED_VALUE"""),"RCEF 23-08-20 Rebidding") -> RCEF 23-08-20 Rebidding | G24: =IFERROR(__xludf.DUMMYFUNCTION("""COMPUTED_VALUE"""),1.0) -> 1 | H24: =IFERROR(__xludf.DUMMYFUNCTION("""COMPUTED_VALUE"""),17382.0) -> 17382 | I24: =IFERROR(__xludf.DUMMYFUNCTION("""COMPUTED_VALUE"""),"KMC 5825 AHPFPV0007") -> KMC 5825 AHPFPV0007 | J24: =IFERROR(__xludf.DUMMYFUNCTION("""COMPUTED_VALUE"""),"PTS100008") -> PTS100008 | K24: =IFERROR(__xludf.DUMMYFUNCTION("""COMPUTED_VALUE"""),"R-SERIES 021 PH") -> R-SERIES 021 PH | L24: =IFERROR(__xludf.DUMMYFUNCTION("""COMPUTED_VALUE"""),"LSGW1750-RMP-2312014") -> LSGW1750-RMP-2312014 | M24: =IFERROR(__xludf.DUMMYFUNCTION("""COMPUTED_VALUE"""),"WDP40-RMP-2312056") -> WDP40-RMP-2312056 | O24: =IFERROR(__xludf.DUMMYFUNCTION("""COMPUTED_VALUE"""),"Balingayan") -> Balingayan | P24: =IFERROR(__xludf.DUMMYFUNCTION("""COMPUTED_VALUE"""),"Calapan City") -> Calapan City | Q24: =IFERROR(__xludf.DUMMYFUNCTION("""COMPUTED_VALUE"""),"Oriental Mindoro") -> Oriental Mindoro | R24: =IFERROR(__xludf.DUMMYFUNCTION("""COMPUTED_VALUE"""),"4B") -> 4B
A25: =IFERROR(__xludf.DUMMYFUNCTION("""COMPUTED_VALUE"""),23.0) -> 23 | B25: =IFERROR(__xludf.DUMMYFUNCTION("""COMPUTED_VALUE"""),"BARANGAY MALINAO FARMERS' ASSOCIATION") -> BARANGAY MALINAO FARMERS' ASSOCIATION | C25: =IFERROR(__xludf.DUMMYFUNCTION("""COMPUTED_VALUE"""),"Malinao, Naujan, Oriental Mindoro") -> Malinao, Naujan, Oriental Mindoro | D25: =IFERROR(__xludf.DUMMYFUNCTION("""COMPUTED_VALUE"""),"ERVIN D. GARILLO") -> ERVIN D. GARILLO | E25: =IFERROR(__xludf.DUMMYFUNCTION("""COMPUTED_VALUE"""),"0956 911 1213") -> 0956 911 1213 | F25: =IFERROR(__xludf.DUMMYFUNCTION("""COMPUTED_VALUE"""),"RCEF 23-08-20 Rebidding") -> RCEF 23-08-20 Rebidding | G25: =IFERROR(__xludf.DUMMYFUNCTION("""COMPUTED_VALUE"""),1.0) -> 1 | H25: =IFERROR(__xludf.DUMMYFUNCTION("""COMPUTED_VALUE"""),17383.0) -> 17383 | I25: =IFERROR(__xludf.DUMMYFUNCTION("""COMPUTED_VALUE"""),"KMC 5825 ACPFPV0012") -> KMC 5825 ACPFPV0012 | J25: =IFERROR(__xludf.DUMMYFUNCTION("""COMPUTED_VALUE"""),"PTS100019") -> PTS100019 | K25: =IFERROR(__xludf.DUMMYFUNCTION("""COMPUTED_VALUE"""),"R-SERIES 049 PH") -> R-SERIES 049 PH | L25: =IFERROR(__xludf.DUMMYFUNCTION("""COMPUTED_VALUE"""),"LSGW1750-RMP-2312003") -> LSGW1750-RMP-2312003 | M25: =IFERROR(__xludf.DUMMYFUNCTION("""COMPUTED_VALUE"""),"WDP40-RMP-2312063") -> WDP40-RMP-2312063 | O25: =IFERROR(__xludf.DUMMYFUNCTION("""COMPUTED_VALUE"""),"Malinao") -> Malinao | P25: =IFERROR(__xludf.DUMMYFUNCTION("""COMPUTED_VALUE"""),"Naujan") -> Naujan | Q25: =IFERROR(__xludf.DUMMYFUNCTION("""COMPUTED_VALUE"""),"Oriental Mindoro") -> Oriental Mindoro | R25: =IFERROR(__xludf.DUMMYFUNCTION("""COMPUTED_VALUE"""),"4B") -> 4B
A26: =IFERROR(__xludf.DUMMYFUNCTION("""COMPUTED_VALUE"""),24.0) -> 24 | B26: =IFERROR(__xludf.DUMMYFUNCTION("""COMPUTED_VALUE"""),"BAGONG BUHAY FARMERS ASSOCIATION") -> BAGONG BUHAY FARMERS ASSOCIATION | C26: =IFERROR(__xludf.DUMMYFUNCTION("""COMPUTED_VALUE"""),"Bagong Buhay, naujan, Oriental Mindoro") -> Bagong Buhay, naujan, Oriental Mindoro | D26: =IFERROR(__xludf.DUMMYFUNCTION("""COMPUTED_VALUE"""),"ERLIN G. PARAY") -> ERLIN G. PARAY | E26: =IFERROR(__xludf.DUMMYFUNCTION("""COMPUTED_VALUE"""),"0907 645 9942") -> 0907 645 9942 | F26: =IFERROR(__xludf.DUMMYFUNCTION("""COMPUTED_VALUE"""),"RCEF 23-08-20 Rebidding") -> RCEF 23-08-20 Rebidding | G26: =IFERROR(__xludf.DUMMYFUNCTION("""COMPUTED_VALUE"""),1.0) -> 1 | H26: =IFERROR(__xludf.DUMMYFUNCTION("""COMPUTED_VALUE"""),17384.0) -> 17384 | I26: =IFERROR(__xludf.DUMMYFUNCTION("""COMPUTED_VALUE"""),"KMC 5825 AHPFPV0038") -> KMC 5825 AHPFPV0038 | J26: =IFERROR(__xludf.DUMMYFUNCTION("""COMPUTED_VALUE"""),"PTS100003") -> PTS100003 | K26: =IFERROR(__xludf.DUMMYFUNCTION("""COMPUTED_VALUE"""),"R-SERIES 034 PH") -> R-SERIES 034 PH | L26: =IFERROR(__xludf.DUMMYFUNCTION("""COMPUTED_VALUE"""),"LSGW1750-RMP-2312034") -> LSGW1750-RMP-2312034 | M26: =IFERROR(__xludf.DUMMYFUNCTION("""COMPUTED_VALUE"""),"WDP40-RMP-2312062") -> WDP40-RMP-2312062 | O26: =IFERROR(__xludf.DUMMYFUNCTION("""COMPUTED_VALUE"""),"Bagong Buhay") -> Bagong Buhay | P26: =IFERROR(__xludf.DUMMYFUNCTION("""COMPUTED_VALUE"""),"Naujan") -> Naujan | Q26: =IFERROR(__xludf.DUMMYFUNCTION("""COMPUTED_VALUE"""),"Oriental Mindoro") -> Oriental Mindoro | R26: =IFERROR(__xludf.DUMMYFUNCTION("""COMPUTED_VALUE"""),"4B") -> 4B
A27: =IFERROR(__xludf.DUMMYFUNCTION("""COMPUTED_VALUE"""),25.0) -> 25 | B27: =IFERROR(__xludf.DUMMYFUNCTION("""COMPUTED_VALUE"""),"SANDIGAN NG MGA MANGGAGAWA SA AGRIKULTURA SA KANAYUNAN (SAMAKA)") -> SANDIGAN NG MGA MANGGAGAWA SA AGRIKULTURA SA KANAYUNAN (SAMAKA) | C27: =IFERROR(__xludf.DUMMYFUNCTION("""COMPUTED_VALUE"""),"Calucmoy, Socorro, Oriental Mindoro") -> Calucmoy, Socorro, Oriental Mindoro | D27: =IFERROR(__xludf.DUMMYFUNCTION("""COMPUTED_VALUE"""),"Edilberto Saez") -> Edilberto Saez | E27: =IFERROR(__xludf.DUMMYFUNCTION("""COMPUTED_VALUE"""),"0948 412 7045") -> 0948 412 7045 | F27: =IFERROR(__xludf.DUMMYFUNCTION("""COMPUTED_VALUE"""),"RCEF 23-08-20 Rebidding") -> RCEF 23-08-20 Rebidding | G27: =IFERROR(__xludf.DUMMYFUNCTION("""COMPUTED_VALUE"""),1.0) -> 1 | H27: =IFERROR(__xludf.DUMMYFUNCTION("""COMPUTED_VALUE"""),17385.0) -> 17385 | I27: =IFERROR(__xludf.DUMMYFUNCTION("""COMPUTED_VALUE"""),"KMC 5825 AVPFPV0018") -> KMC 5825 AVPFPV0018 | J27: =IFERROR(__xludf.DUMMYFUNCTION("""COMPUTED_VALUE"""),"PTS100037") -> PTS100037 | K27: =IFERROR(__xludf.DUMMYFUNCTION("""COMPUTED_VALUE"""),"R-SERIES 005 PH") -> R-SERIES 005 PH | L27: =IFERROR(__xludf.DUMMYFUNCTION("""COMPUTED_VALUE"""),"LSGW1750-RMP-2312012") -> LSGW1750-RMP-2312012 | M27: =IFERROR(__xludf.DUMMYFUNCTION("""COMPUTED_VALUE"""),"WDP40-RMP-2312057") -> WDP40-RMP-2312057 | O27: =IFERROR(__xludf.DUMMYFUNCTION("""COMPUTED_VALUE"""),"Calucmoy") -> Calucmoy | P27: =IFERROR(__xludf.DUMMYFUNCTION("""COMPUTED_VALUE"""),"Socorro") -> Socorro | Q27: =IFERROR(__xludf.DUMMYFUNCTION("""COMPUTED_VALUE"""),"Oriental Mindoro") -> Oriental Mindoro | R27: =IFERROR(__xludf.DUMMYFUNCTION("""COMPUTED_VALUE"""),"4B") -> 4B
A28: =IFERROR(__xludf.DUMMYFUNCTION("""COMPUTED_VALUE"""),26.0) -> 26 | B28: =IFERROR(__xludf.DUMMYFUNCTION("""COMPUTED_VALUE"""),"MACATOC FARMERS ASSOCIATION") -> MACATOC FARMERS ASSOCIATION | C28: =IFERROR(__xludf.DUMMYFUNCTION("""COMPUTED_VALUE"""),"Macatoc, Victoria, Oriental Mindoro") -> Macatoc, Victoria, Oriental Mindoro | D28: =IFERROR(__xludf.DUMMYFUNCTION("""COMPUTED_VALUE"""),"DENVER J. PERICO") -> DENVER J. PERICO | E28: =IFERROR(__xludf.DUMMYFUNCTION("""COMPUTED_VALUE"""),"0909 489 2967") -> 0909 489 2967 | F28: =IFERROR(__xludf.DUMMYFUNCTION("""COMPUTED_VALUE"""),"RCEF 23-08-20 Rebidding") -> RCEF 23-08-20 Rebidding | G28: =IFERROR(__xludf.DUMMYFUNCTION("""COMPUTED_VALUE"""),1.0) -> 1 | H28: =IFERROR(__xludf.DUMMYFUNCTION("""COMPUTED_VALUE"""),17386.0) -> 17386 | I28: =IFERROR(__xludf.DUMMYFUNCTION("""COMPUTED_VALUE"""),"KMC 5825 ALPFPV0040") -> KMC 5825 ALPFPV0040 | J28: =IFERROR(__xludf.DUMMYFUNCTION("""COMPUTED_VALUE"""),"PTS100011") -> PTS100011 | K28: =IFERROR(__xludf.DUMMYFUNCTION("""COMPUTED_VALUE"""),"R-SERIES 018 PH") -> R-SERIES 018 PH | L28: =IFERROR(__xludf.DUMMYFUNCTION("""COMPUTED_VALUE"""),"LSGW1750-RMP-2312002") -> LSGW1750-RMP-2312002 | M28: =IFERROR(__xludf.DUMMYFUNCTION("""COMPUTED_VALUE"""),"WDP40-RMP-2312058") -> WDP40-RMP-2312058 | O28: =IFERROR(__xludf.DUMMYFUNCTION("""COMPUTED_VALUE"""),"Macatoc") -> Macatoc | P28: =IFERROR(__xludf.DUMMYFUNCTION("""COMPUTED_VALUE"""),"Victoria") -> Victoria | Q28: =IFERROR(__xludf.DUMMYFUNCTION("""COMPUTED_VALUE"""),"Oriental Mindoro") -> Oriental Mindoro | R28: =IFERROR(__xludf.DUMMYFUNCTION("""COMPUTED_VALUE"""),"4B") -> 4B
A29: =IFERROR(__xludf.DUMMYFUNCTION("""COMPUTED_VALUE"""),27.0) -> 27 | B29: =IFERROR(__xludf.DUMMYFUNCTION("""COMPUTED_VALUE"""),"SAN NICOLAS SMALL WATER IRRIGATION SYSTEM ASSOCIATION") -> SAN NICOLAS SMALL WATER IRRIGATION SYSTEM ASSOCIATION | C29: =IFERROR(__xludf.DUMMYFUNCTION("""COMPUTED_VALUE"""),"Rosacara, Bansud, Oriental Mindoro") -> Rosacara, Bansud, Oriental Mindoro | D29: =IFERROR(__xludf.DUMMYFUNCTION("""COMPUTED_VALUE"""),"EDGARDO M. CASAPAO") -> EDGARDO M. CASAPAO | E29: =IFERROR(__xludf.DUMMYFUNCTION("""COMPUTED_VALUE"""),9.071476723E9) -> 9071476723 | F29: =IFERROR(__xludf.DUMMYFUNCTION("""COMPUTED_VALUE"""),"RCEF 23-08-20 Rebidding") -> RCEF 23-08-20 Rebidding | G29: =IFERROR(__xludf.DUMMYFUNCTION("""COMPUTED_VALUE"""),1.0) -> 1 | H29: =IFERROR(__xludf.DUMMYFUNCTION("""COMPUTED_VALUE"""),17387.0) -> 17387 | I29: =IFERROR(__xludf.DUMMYFUNCTION("""COMPUTED_VALUE"""),"KMC 5825 APPFPV0028") -> KMC 5825 APPFPV0028 | J29: =IFERROR(__xludf.DUMMYFUNCTION("""COMPUTED_VALUE"""),"PTS100021") -> PTS100021 | K29: =IFERROR(__xludf.DUMMYFUNCTION("""COMPUTED_VALUE"""),"R-SERIES 025 PH") -> R-SERIES 025 PH | L29: =IFERROR(__xludf.DUMMYFUNCTION("""COMPUTED_VALUE"""),"LSGW1750-RMP-2312027") -> LSGW1750-RMP-2312027 | M29: =IFERROR(__xludf.DUMMYFUNCTION("""COMPUTED_VALUE"""),"WDP40-RMP-2312038") -> WDP40-RMP-2312038 | O29: =IFERROR(__xludf.DUMMYFUNCTION("""COMPUTED_VALUE"""),"Rosacara") -> Rosacara | P29: =IFERROR(__xludf.DUMMYFUNCTION("""COMPUTED_VALUE"""),"Bansud") -> Bansud | Q29: =IFERROR(__xludf.DUMMYFUNCTION("""COMPUTED_VALUE"""),"Oriental Mindoro") -> Oriental Mindoro | R29: =IFERROR(__xludf.DUMMYFUNCTION("""COMPUTED_VALUE"""),"4B") -> 4B
A30: =IFERROR(__xludf.DUMMYFUNCTION("""COMPUTED_VALUE"""),28.0) -> 28 | B30: =IFERROR(__xludf.DUMMYFUNCTION("""COMPUTED_VALUE"""),"ALCADESMA GROUP OF FARMERS ASSOCIATION(AGFA)") -> ALCADESMA GROUP OF FARMERS ASSOCIATION(AGFA) | C30: =IFERROR(__xludf.DUMMYFUNCTION("""COMPUTED_VALUE"""),"Alcadesma, Bansud, Oriental Mindoro") -> Alcadesma, Bansud, Oriental Mindoro | D30: =IFERROR(__xludf.DUMMYFUNCTION("""COMPUTED_VALUE"""),"ROMEO R. YAP") -> ROMEO R. YAP | E30: =IFERROR(__xludf.DUMMYFUNCTION("""COMPUTED_VALUE"""),"0920 540 2742") -> 0920 540 2742 | F30: =IFERROR(__xludf.DUMMYFUNCTION("""COMPUTED_VALUE"""),"RCEF 23-08-20 Rebidding") -> RCEF 23-08-20 Rebidding | G30: =IFERROR(__xludf.DUMMYFUNCTION("""COMPUTED_VALUE"""),1.0) -> 1 | H30: =IFERROR(__xludf.DUMMYFUNCTION("""COMPUTED_VALUE"""),17388.0) -> 17388 | I30: =IFERROR(__xludf.DUMMYFUNCTION("""COMPUTED_VALUE"""),"KMC 5825 ACPFPV0020") -> KMC 5825 ACPFPV0020 | J30: =IFERROR(__xludf.DUMMYFUNCTION("""COMPUTED_VALUE"""),"PTS100036") -> PTS100036 | K30: =IFERROR(__xludf.DUMMYFUNCTION("""COMPUTED_VALUE"""),"R-SERIES 012 PH") -> R-SERIES 012 PH | L30: =IFERROR(__xludf.DUMMYFUNCTION("""COMPUTED_VALUE"""),"LSGW1750-RMP-2312013") -> LSGW1750-RMP-2312013 | M30: =IFERROR(__xludf.DUMMYFUNCTION("""COMPUTED_VALUE"""),"WDP40-RMP-2312049") -> WDP40-RMP-2312049 | O30: =IFERROR(__xludf.DUMMYFUNCTION("""COMPUTED_VALUE"""),"Alcadesma") -> Alcadesma | P30: =IFERROR(__xludf.DUMMYFUNCTION("""COMPUTED_VALUE"""),"Bansud") -> Bansud | Q30: =IFERROR(__xludf.DUMMYFUNCTION("""COMPUTED_VALUE"""),"Oriental Mindoro") -> Oriental Mindoro | R30: =IFERROR(__xludf.DUMMYFUNCTION("""COMPUTED_VALUE"""),"4B") -> 4B
A31: =IFERROR(__xludf.DUMMYFUNCTION("""COMPUTED_VALUE"""),29.0) -> 29 | B31: =IFERROR(__xludf.DUMMYFUNCTION("""COMPUTED_VALUE"""),"A. BONIFACIO FARMERS ASSOCIATION") -> A. BONIFACIO FARMERS ASSOCIATION | C31: =IFERROR(__xludf.DUMMYFUNCTION("""COMPUTED_VALUE"""),"A. Bonifacio, Gloria, Oriental Mindoro") -> A. Bonifacio, Gloria, Oriental Mindoro | D31: =IFERROR(__xludf.DUMMYFUNCTION("""COMPUTED_VALUE"""),"GILBERT R. MALANOG") -> GILBERT R. MALANOG | E31: =IFERROR(__xludf.DUMMYFUNCTION("""COMPUTED_VALUE"""),"0912 838 9639") -> 0912 838 9639 | F31: =IFERROR(__xludf.DUMMYFUNCTION("""COMPUTED_VALUE"""),"RCEF 23-08-20 Rebidding") -> RCEF 23-08-20 Rebidding | G31: =IFERROR(__xludf.DUMMYFUNCTION("""COMPUTED_VALUE"""),1.0) -> 1 | H31: =IFERROR(__xludf.DUMMYFUNCTION("""COMPUTED_VALUE"""),17389.0) -> 17389 | I31: =IFERROR(__xludf.DUMMYFUNCTION("""COMPUTED_VALUE"""),"KMC 5825 ACPFPV0079") -> KMC 5825 ACPFPV0079 | J31: =IFERROR(__xludf.DUMMYFUNCTION("""COMPUTED_VALUE"""),"PTS100081") -> PTS100081 | K31: =IFERROR(__xludf.DUMMYFUNCTION("""COMPUTED_VALUE"""),"R-SERIES 020 PH") -> R-SERIES 020 PH | L31: =IFERROR(__xludf.DUMMYFUNCTION("""COMPUTED_VALUE"""),"LSGW1750-RMP-2312001") -> LSGW1750-RMP-2312001 | M31: =IFERROR(__xludf.DUMMYFUNCTION("""COMPUTED_VALUE"""),"WDP40-RMP-2312065") -> WDP40-RMP-2312065 | O31: =IFERROR(__xludf.DUMMYFUNCTION("""COMPUTED_VALUE"""),"A. Bonifacio") -> A. Bonifacio | P31: =IFERROR(__xludf.DUMMYFUNCTION("""COMPUTED_VALUE"""),"Gloria") -> Gloria | Q31: =IFERROR(__xludf.DUMMYFUNCTION("""COMPUTED_VALUE"""),"Oriental Mindoro") -> Oriental Mindoro | R31: =IFERROR(__xludf.DUMMYFUNCTION("""COMPUTED_VALUE"""),"4B") -> 4B
A32: =IFERROR(__xludf.DUMMYFUNCTION("""COMPUTED_VALUE"""),30.0) -> 30 | B32: =IFERROR(__xludf.DUMMYFUNCTION("""COMPUTED_VALUE"""),"BARANGAY NABUSLOT PINAMALAYAN FARMERS ASSOCIATION INC.") -> BARANGAY NABUSLOT PINAMALAYAN FARMERS ASSOCIATION INC. | C32: =IFERROR(__xludf.DUMMYFUNCTION("""COMPUTED_VALUE"""),"Nabuslot, Pinamalayan, Oriental Mindoro") -> Nabuslot, Pinamalayan, Oriental Mindoro | D32: =IFERROR(__xludf.DUMMYFUNCTION("""COMPUTED_VALUE"""),"NICANOR J. LUMALANG") -> NICANOR J. LUMALANG | E32: =IFERROR(__xludf.DUMMYFUNCTION("""COMPUTED_VALUE"""),"0917 563 3431") -> 0917 563 3431 | F32: =IFERROR(__xludf.DUMMYFUNCTION("""COMPUTED_VALUE"""),"RCEF 23-08-20 Rebidding") -> RCEF 23-08-20 Rebidding | G32: =IFERROR(__xludf.DUMMYFUNCTION("""COMPUTED_VALUE"""),1.0) -> 1 | H32: =IFERROR(__xludf.DUMMYFUNCTION("""COMPUTED_VALUE"""),17390.0) -> 17390 | I32: =IFERROR(__xludf.DUMMYFUNCTION("""COMPUTED_VALUE"""),"KMC 5825 AHPFPV0024") -> KMC 5825 AHPFPV0024 | J32: =IFERROR(__xludf.DUMMYFUNCTION("""COMPUTED_VALUE"""),"PTS100035") -> PTS100035 | K32: =IFERROR(__xludf.DUMMYFUNCTION("""COMPUTED_VALUE"""),"R-SERIES 017 PH") -> R-SERIES 017 PH | L32: =IFERROR(__xludf.DUMMYFUNCTION("""COMPUTED_VALUE"""),"LSGW1750-RMP-2312026") -> LSGW1750-RMP-2312026 | M32: =IFERROR(__xludf.DUMMYFUNCTION("""COMPUTED_VALUE"""),"WDP40-RMP-2312061") -> WDP40-RMP-2312061 | O32: =IFERROR(__xludf.DUMMYFUNCTION("""COMPUTED_VALUE"""),"Nabuslot") -> Nabuslot | P32: =IFERROR(__xludf.DUMMYFUNCTION("""COMPUTED_VALUE"""),"Pinamalayan") -> Pinamalayan | Q32: =IFERROR(__xludf.DUMMYFUNCTION("""COMPUTED_VALUE"""),"Oriental Mindoro") -> Oriental Mindoro | R32: =IFERROR(__xludf.DUMMYFUNCTION("""COMPUTED_VALUE"""),"4B") -> 4B
A33: =IFERROR(__xludf.DUMMYFUNCTION("""COMPUTED_VALUE"""),31.0) -> 31 | B33: =IFERROR(__xludf.DUMMYFUNCTION("""COMPUTED_VALUE"""),"CANTIL FARMERS ASSOCIATION") -> CANTIL FARMERS ASSOCIATION | C33: =IFERROR(__xludf.DUMMYFUNCTION("""COMPUTED_VALUE"""),"Cantil, Roxas, Oriental Mindoro") -> Cantil, Roxas, Oriental Mindoro | D33: =IFERROR(__xludf.DUMMYFUNCTION("""COMPUTED_VALUE"""),"ANGELO S. ANDRES") -> ANGELO S. ANDRES | E33: =IFERROR(__xludf.DUMMYFUNCTION("""COMPUTED_VALUE"""),"0938 348 2989") -> 0938 348 2989 | F33: =IFERROR(__xludf.DUMMYFUNCTION("""COMPUTED_VALUE"""),"RCEF 23-08-20 Rebidding") -> RCEF 23-08-20 Rebidding | G33: =IFERROR(__xludf.DUMMYFUNCTION("""COMPUTED_VALUE"""),1.0) -> 1 | H33: =IFERROR(__xludf.DUMMYFUNCTION("""COMPUTED_VALUE"""),17391.0) -> 17391 | I33: =IFERROR(__xludf.DUMMYFUNCTION("""COMPUTED_VALUE"""),"KMC 5825 AAPFPV0022") -> KMC 5825 AAPFPV0022 | J33: =IFERROR(__xludf.DUMMYFUNCTION("""COMPUTED_VALUE"""),"PTS100026") -> PTS100026 | K33: =IFERROR(__xludf.DUMMYFUNCTION("""COMPUTED_VALUE"""),"R-SERIES 024 PH") -> R-SERIES 024 PH | L33: =IFERROR(__xludf.DUMMYFUNCTION("""COMPUTED_VALUE"""),"LSGW1750-RMP-2312025") -> LSGW1750-RMP-2312025 | M33: =IFERROR(__xludf.DUMMYFUNCTION("""COMPUTED_VALUE"""),"WDP40-RMP-2312066") -> WDP40-RMP-2312066 | O33: =IFERROR(__xludf.DUMMYFUNCTION("""COMPUTED_VALUE"""),"Cantil") -> Cantil | P33: =IFERROR(__xludf.DUMMYFUNCTION("""COMPUTED_VALUE"""),"Roxas") -> Roxas | Q33: =IFERROR(__xludf.DUMMYFUNCTION("""COMPUTED_VALUE"""),"Oriental Mindoro") -> Oriental Mindoro | R33: =IFERROR(__xludf.DUMMYFUNCTION("""COMPUTED_VALUE"""),"4B") -> 4B
A34: =IFERROR(__xludf.DUMMYFUNCTION("""COMPUTED_VALUE"""),32.0) -> 32 | B34: =IFERROR(__xludf.DUMMYFUNCTION("""COMPUTED_VALUE"""),"BAGUMBAYAN ROXAS ORIENTAL MINDORO FARMERS ASSOCIATION") -> BAGUMBAYAN ROXAS ORIENTAL MINDORO FARMERS ASSOCIATION | C34: =IFERROR(__xludf.DUMMYFUNCTION("""COMPUTED_VALUE"""),"Bagumbayan, Roxas, Oriental Mindoro") -> Bagumbayan, Roxas, Oriental Mindoro | D34: =IFERROR(__xludf.DUMMYFUNCTION("""COMPUTED_VALUE"""),"GIOVANI A. GAA") -> GIOVANI A. GAA | E34: =IFERROR(__xludf.DUMMYFUNCTION("""COMPUTED_VALUE"""),"0930 479 0163") -> 0930 479 0163 | F34: =IFERROR(__xludf.DUMMYFUNCTION("""COMPUTED_VALUE"""),"RCEF 23-08-20 Rebidding") -> RCEF 23-08-20 Rebidding | G34: =IFERROR(__xludf.DUMMYFUNCTION("""COMPUTED_VALUE"""),1.0) -> 1 | H34: =IFERROR(__xludf.DUMMYFUNCTION("""COMPUTED_VALUE"""),17392.0) -> 17392 | I34: =IFERROR(__xludf.DUMMYFUNCTION("""COMPUTED_VALUE"""),"KMC 5825 ACPFPV0017") -> KMC 5825 ACPFPV0017 | J34: =IFERROR(__xludf.DUMMYFUNCTION("""COMPUTED_VALUE"""),"PTS100032") -> PTS100032 | K34: =IFERROR(__xludf.DUMMYFUNCTION("""COMPUTED_VALUE"""),"R-SERIES 001 PH") -> R-SERIES 001 PH | L34: =IFERROR(__xludf.DUMMYFUNCTION("""COMPUTED_VALUE"""),"LSGW1750-RMP-2312015") -> LSGW1750-RMP-2312015 | M34: =IFERROR(__xludf.DUMMYFUNCTION("""COMPUTED_VALUE"""),"WDP40-RMP-2312059") -> WDP40-RMP-2312059 | O34: =IFERROR(__xludf.DUMMYFUNCTION("""COMPUTED_VALUE"""),"Bagumbayan") -> Bagumbayan | P34: =IFERROR(__xludf.DUMMYFUNCTION("""COMPUTED_VALUE"""),"Roxas") -> Roxas | Q34: =IFERROR(__xludf.DUMMYFUNCTION("""COMPUTED_VALUE"""),"Oriental Mindoro") -> Oriental Mindoro | R34: =IFERROR(__xludf.DUMMYFUNCTION("""COMPUTED_VALUE"""),"4B") -> 4B
A35: =IFERROR(__xludf.DUMMYFUNCTION("""COMPUTED_VALUE"""),33.0) -> 33 | B35: =IFERROR(__xludf.DUMMYFUNCTION("""COMPUTED_VALUE"""),"Municipal Local Government Unit of Cavinti") -> Municipal Local Government Unit of Cavinti | C35: =IFERROR(__xludf.DUMMYFUNCTION("""COMPUTED_VALUE"""),"Poblacion, Cavinti, Laguna") -> Poblacion, Cavinti, Laguna | D35: =IFERROR(__xludf.DUMMYFUNCTION("""COMPUTED_VALUE"""),"Hon. Milbert L. Olivares") -> Hon. Milbert L. Olivares | E35: =IFERROR(__xludf.DUMMYFUNCTION("""COMPUTED_VALUE"""),"0919 002 7529") -> 0919 002 7529 | F35: =IFERROR(__xludf.DUMMYFUNCTION("""COMPUTED_VALUE"""),"RCEF 23-08-20 Rebidding") -> RCEF 23-08-20 Rebidding | G35: =IFERROR(__xludf.DUMMYFUNCTION("""COMPUTED_VALUE"""),1.0) -> 1 | H35: =IFERROR(__xludf.DUMMYFUNCTION("""COMPUTED_VALUE"""),17706.0) -> 17706 | I35: =IFERROR(__xludf.DUMMYFUNCTION("""COMPUTED_VALUE"""),"KMC 5825 ACPFPV0141") -> KMC 5825 ACPFPV0141 | J35: =IFERROR(__xludf.DUMMYFUNCTION("""COMPUTED_VALUE"""),"PTS100076") -> PTS100076 | K35: =IFERROR(__xludf.DUMMYFUNCTION("""COMPUTED_VALUE"""),"R-SERIES 002 PH") -> R-SERIES 002 PH | L35: =IFERROR(__xludf.DUMMYFUNCTION("""COMPUTED_VALUE"""),"LSGW1750-RMP-2312177") -> LSGW1750-RMP-2312177 | M35: =IFERROR(__xludf.DUMMYFUNCTION("""COMPUTED_VALUE"""),"WDP40-RMP-2312113") -> WDP40-RMP-2312113 | O35: =IFERROR(__xludf.DUMMYFUNCTION("""COMPUTED_VALUE"""),"Poblacion") -> Poblacion | P35: =IFERROR(__xludf.DUMMYFUNCTION("""COMPUTED_VALUE"""),"Cavinti") -> Cavinti | Q35: =IFERROR(__xludf.DUMMYFUNCTION("""COMPUTED_VALUE"""),"Laguna") -> Laguna | R35: =IFERROR(__xludf.DUMMYFUNCTION("""COMPUTED_VALUE"""),"4A") -> 4A
A36: =IFERROR(__xludf.DUMMYFUNCTION("""COMPUTED_VALUE"""),34.0) -> 34 | B36: =IFERROR(__xludf.DUMMYFUNCTION("""COMPUTED_VALUE"""),"Municipal Local Government Unit of Kalayaan") -> Municipal Local Government Unit of Kalayaan | C36: =IFERROR(__xludf.DUMMYFUNCTION("""COMPUTED_VALUE"""),"San Juan, Kalayaan, Laguna") -> San Juan, Kalayaan, Laguna | D36: =IFERROR(__xludf.DUMMYFUNCTION("""COMPUTED_VALUE"""),"Hon. Sandy P. Laganapan") -> Hon. Sandy P. Laganapan | E36: =IFERROR(__xludf.DUMMYFUNCTION("""COMPUTED_VALUE"""),"0926 242 9624") -> 0926 242 9624 | F36: =IFERROR(__xludf.DUMMYFUNCTION("""COMPUTED_VALUE"""),"RCEF 23-08-20 Rebidding") -> RCEF 23-08-20 Rebidding | G36: =IFERROR(__xludf.DUMMYFUNCTION("""COMPUTED_VALUE"""),1.0) -> 1 | H36: =IFERROR(__xludf.DUMMYFUNCTION("""COMPUTED_VALUE"""),17707.0) -> 17707 | I36: =IFERROR(__xludf.DUMMYFUNCTION("""COMPUTED_VALUE"""),"KMC 5825 AAPFPV0067") -> KMC 5825 AAPFPV0067 | J36: =IFERROR(__xludf.DUMMYFUNCTION("""COMPUTED_VALUE"""),"PTS100150") -> PTS100150 | K36: =IFERROR(__xludf.DUMMYFUNCTION("""COMPUTED_VALUE"""),"R-SERIES 008 PH") -> R-SERIES 008 PH | L36: =IFERROR(__xludf.DUMMYFUNCTION("""COMPUTED_VALUE"""),"LSGW1750-RMP-2312079") -> LSGW1750-RMP-2312079 | M36: =IFERROR(__xludf.DUMMYFUNCTION("""COMPUTED_VALUE"""),"WDP40-RMP-2312074") -> WDP40-RMP-2312074 | O36: =IFERROR(__xludf.DUMMYFUNCTION("""COMPUTED_VALUE"""),"San Juan") -> San Juan | P36: =IFERROR(__xludf.DUMMYFUNCTION("""COMPUTED_VALUE"""),"Kalayaan") -> Kalayaan | Q36: =IFERROR(__xludf.DUMMYFUNCTION("""COMPUTED_VALUE"""),"Laguna") -> Laguna | R36: =IFERROR(__xludf.DUMMYFUNCTION("""COMPUTED_VALUE"""),"4A") -> 4A
A37: =IFERROR(__xludf.DUMMYFUNCTION("""COMPUTED_VALUE"""),35.0) -> 35 | B37: =IFERROR(__xludf.DUMMYFUNCTION("""COMPUTED_VALUE"""),"SAMAHAN NG MAGSASAKA NG BARANGAY NANGUMA (SAMABANA)") -> SAMAHAN NG MAGSASAKA NG BARANGAY NANGUMA (SAMABANA) | C37: =IFERROR(__xludf.DUMMYFUNCTION("""COMPUTED_VALUE"""),"Nanguma, Mabitac, Laguna") -> Nanguma, Mabitac, Laguna | D37: =IFERROR(__xludf.DUMMYFUNCTION("""COMPUTED_VALUE"""),"LORETO D. PEREZ") -> LORETO D. PEREZ | E37: =IFERROR(__xludf.DUMMYFUNCTION("""COMPUTED_VALUE"""),"0927-910-0483") -> 0927-910-0483 | F37: =IFERROR(__xludf.DUMMYFUNCTION("""COMPUTED_VALUE"""),"RCEF 23-08-20 Rebidding") -> RCEF 23-08-20 Rebidding | G37: =IFERROR(__xludf.DUMMYFUNCTION("""COMPUTED_VALUE"""),1.0) -> 1 | H37: =IFERROR(__xludf.DUMMYFUNCTION("""COMPUTED_VALUE"""),17708.0) -> 17708 | I37: =IFERROR(__xludf.DUMMYFUNCTION("""COMPUTED_VALUE"""),"KMC 5825 ATPFPV0111") -> KMC 5825 ATPFPV0111 | J37: =IFERROR(__xludf.DUMMYFUNCTION("""COMPUTED_VALUE"""),"PTS100093") -> PTS100093 | K37: =IFERROR(__xludf.DUMMYFUNCTION("""COMPUTED_VALUE"""),"R-SERIES 017 PH") -> R-SERIES 017 PH | L37: =IFERROR(__xludf.DUMMYFUNCTION("""COMPUTED_VALUE"""),"LSGW1750-RMP-2312161") -> LSGW1750-RMP-2312161 | M37: =IFERROR(__xludf.DUMMYFUNCTION("""COMPUTED_VALUE"""),"WDP40-RMP-2401005") -> WDP40-RMP-2401005 | O37: =IFERROR(__xludf.DUMMYFUNCTION("""COMPUTED_VALUE"""),"Nanguma") -> Nanguma | P37: =IFERROR(__xludf.DUMMYFUNCTION("""COMPUTED_VALUE"""),"Mabitac") -> Mabitac | Q37: =IFERROR(__xludf.DUMMYFUNCTION("""COMPUTED_VALUE"""),"Laguna") -> Laguna | R37: =IFERROR(__xludf.DUMMYFUNCTION("""COMPUTED_VALUE"""),"4A") -> 4A
